try {
	
} catch(const std::exception& e) {
	
}