try { 
} catch(Exception varName) {

} catch(Exception2 varName) {

}